{"uuid": "8cd269ea-9330-47c5-9cd1-030ead9e9b33", "children": ["2c17221c-54af-4136-bfd9-4b5bdc531e9d"], "befores": [{"name": "created_courier", "status": "broken", "statusDetails": {"message": "requests.exceptions.ConnectTimeout: HTTPSConnectionPool(host='qa-scooter.praktikum-services.ru', port=443): Max retries exceeded with url: /api/v1/courier (Caused by ConnectTimeoutError(<urllib3.connection.HTTPSConnection object at 0x00000254AB387250>, 'Connection to qa-scooter.praktikum-services.ru timed out. (connect timeout=None)'))\n", "trace": "  File \"C:\\Users\\there\\AppData\\Local\\Programs\\Python\\Python313\\Lib\\site-packages\\pluggy\\_callers.py\", line 38, in run_old_style_hookwrapper\n    res = yield\n          ^^^^^\n  File \"C:\\Users\\there\\AppData\\Local\\Programs\\Python\\Python313\\Lib\\site-packages\\pluggy\\_callers.py\", line 139, in _multicall\n    teardown.throw(exception)\n    ~~~~~~~~~~~~~~^^^^^^^^^^^\n  File \"C:\\Users\\there\\AppData\\Local\\Programs\\Python\\Python313\\Lib\\site-packages\\_pytest\\setuponly.py\", line 36, in pytest_fixture_setup\n    return (yield)\n            ^^^^^\n  File \"C:\\Users\\there\\AppData\\Local\\Programs\\Python\\Python313\\Lib\\site-packages\\pluggy\\_callers.py\", line 121, in _multicall\n    res = hook_impl.function(*args)\n  File \"C:\\Users\\there\\AppData\\Local\\Programs\\Python\\Python313\\Lib\\site-packages\\_pytest\\fixtures.py\", line 1140, in pytest_fixture_setup\n    result = call_fixture_func(fixturefunc, request, kwargs)\n  File \"C:\\Users\\there\\AppData\\Local\\Programs\\Python\\Python313\\Lib\\site-packages\\_pytest\\fixtures.py\", line 891, in call_fixture_func\n    fixture_result = next(generator)\n  File \"C:\\Users\\there\\Sprint_7\\conftest.py\", line 30, in created_courier\n    response = CourierAPI.create_courier(courier_data)\n  File \"C:\\Users\\there\\AppData\\Local\\Programs\\Python\\Python313\\Lib\\site-packages\\allure_commons\\_allure.py\", line 192, in impl\n    return func(*a, **kw)\n  File \"C:\\Users\\there\\Sprint_7\\api\\courier_api.py\", line 20, in create_courier\n    return requests.post(COURIER_CREATE, json=payload)\n           ~~~~~~~~~~~~~^^^^^^^^^^^^^^^^^^^^^^^^^^^^^^\n  File \"C:\\Users\\there\\AppData\\Local\\Programs\\Python\\Python313\\Lib\\site-packages\\requests\\api.py\", line 115, in post\n    return request(\"post\", url, data=data, json=json, **kwargs)\n  File \"C:\\Users\\there\\AppData\\Local\\Programs\\Python\\Python313\\Lib\\site-packages\\requests\\api.py\", line 59, in request\n    return session.request(method=method, url=url, **kwargs)\n           ~~~~~~~~~~~~~~~^^^^^^^^^^^^^^^^^^^^^^^^^^^^^^^^^^\n  File \"C:\\Users\\there\\AppData\\Local\\Programs\\Python\\Python313\\Lib\\site-packages\\requests\\sessions.py\", line 589, in request\n    resp = self.send(prep, **send_kwargs)\n  File \"C:\\Users\\there\\AppData\\Local\\Programs\\Python\\Python313\\Lib\\site-packages\\requests\\sessions.py\", line 703, in send\n    r = adapter.send(request, **kwargs)\n  File \"C:\\Users\\there\\AppData\\Local\\Programs\\Python\\Python313\\Lib\\site-packages\\requests\\adapters.py\", line 507, in send\n    raise ConnectTimeout(e, request=request)\n"}, "steps": [{"name": "Создать курьера", "status": "broken", "statusDetails": {"message": "requests.exceptions.ConnectTimeout: HTTPSConnectionPool(host='qa-scooter.praktikum-services.ru', port=443): Max retries exceeded with url: /api/v1/courier (Caused by ConnectTimeoutError(<urllib3.connection.HTTPSConnection object at 0x00000254AB387250>, 'Connection to qa-scooter.praktikum-services.ru timed out. (connect timeout=None)'))\n", "trace": "  File \"C:\\Users\\there\\AppData\\Local\\Programs\\Python\\Python313\\Lib\\site-packages\\allure_commons\\_allure.py\", line 192, in impl\n    return func(*a, **kw)\n  File \"C:\\Users\\there\\Sprint_7\\api\\courier_api.py\", line 20, in create_courier\n    return requests.post(COURIER_CREATE, json=payload)\n           ~~~~~~~~~~~~~^^^^^^^^^^^^^^^^^^^^^^^^^^^^^^\n  File \"C:\\Users\\there\\AppData\\Local\\Programs\\Python\\Python313\\Lib\\site-packages\\requests\\api.py\", line 115, in post\n    return request(\"post\", url, data=data, json=json, **kwargs)\n  File \"C:\\Users\\there\\AppData\\Local\\Programs\\Python\\Python313\\Lib\\site-packages\\requests\\api.py\", line 59, in request\n    return session.request(method=method, url=url, **kwargs)\n           ~~~~~~~~~~~~~~~^^^^^^^^^^^^^^^^^^^^^^^^^^^^^^^^^^\n  File \"C:\\Users\\there\\AppData\\Local\\Programs\\Python\\Python313\\Lib\\site-packages\\requests\\sessions.py\", line 589, in request\n    resp = self.send(prep, **send_kwargs)\n  File \"C:\\Users\\there\\AppData\\Local\\Programs\\Python\\Python313\\Lib\\site-packages\\requests\\sessions.py\", line 703, in send\n    r = adapter.send(request, **kwargs)\n  File \"C:\\Users\\there\\AppData\\Local\\Programs\\Python\\Python313\\Lib\\site-packages\\requests\\adapters.py\", line 507, in send\n    raise ConnectTimeout(e, request=request)\n"}, "parameters": [{"name": "payload", "value": "{'login': 'thxezlncbk', 'password': 'cipyhgtcgl', 'firstName': 'csdjoagtfp'}"}], "start": 1761487069131, "stop": 1761487090183}], "start": 1761487069131, "stop": 1761487090185}], "start": 1761487069131, "stop": 1761487090228}